Workbook

Sheet GLOBAL
B2: UPC - EETAC - EA-M QP2526 Grup 3: Còmput de les hores de treball del projecte ViveBook
B4: Secció | D4: Alba | E4: Marc | F4: Muye | G4: Victor | H4: Wenjie | J4: Grup
B6: Backend | D6: =SUM(ALBA!F5:F138) -> 17 | E6: =SUM(MARC!F5:F138) -> 21 | F6: =SUM(MUYE!F5:F138) -> 27 | G6: =SUM(VICTOR!F5:F138) -> 19.5 | H6: =SUM(WENJIE!F5:F138) -> 32 | J6: =SUM(D6:H6) -> 116.5
B8: BackOffice | D8: =SUM(ALBA!I5:I138) -> 5 | E8: =SUM(MARC!I5:I138) -> 8 | F8: =SUM(MUYE!I5:I138) -> 5 | G8: =SUM(VICTOR!I5:I138) -> 15 | H8: =SUM(WENJIE!I5:I138) -> 7.5 | J8: =SUM(D8:H8) -> 40.5
B10: App Web | D10: =SUM(ALBA!L5:L138) -> 6.5 | E10: =SUM(MARC!L5:L138) -> 11.5 | F10: =SUM(MUYE!L5:L138) -> 4.5 | G10: =SUM(VICTOR!L5:L138) -> 6.5 | H10: =SUM(WENJIE!L5:L138) -> 14 | J10: =SUM(D10:H10) -> 43
B12: App Mobile | D12: =SUM(ALBA!O5:O138) -> 22.5 | E12: =SUM(MARC!O5:O138) -> 9.5 | F12: =SUM(MUYE!O5:O138) -> 19.5 | G12: =SUM(VICTOR!O5:O138) -> 4.5 | H12: =SUM(WENJIE!O5:O138) -> 21.5 | J12: =SUM(D12:H12) -> 77.5
B14: Gestió | D14: =SUM(ALBA!R5:R138) -> 23 | E14: =SUM(MARC!R5:R138) -> 22 | F14: =SUM(MUYE!R5:R138) -> 17 | G14: =SUM(VICTOR!R5:R138) -> 31 | H14: =SUM(WENJIE!R5:R138) -> 25 | J14: =SUM(D14:H14) -> 118
B16: Total | D16: =SUM(D6:D14) -> 74 | E16: =SUM(E6:E14) -> 72 | F16: =SUM(F6:F14) -> 73 | G16: =SUM(G6:G14) -> 76.5 | H16: =SUM(H6:H14) -> 100 | J16: =SUM(D16:H16) -> 395.5

Sheet ALBA
B2: ALBA | F2: BACKEND | I2: BACKOFFICE | L2: APP WEB | O2: APP MOBILE | R2: GESTIÓ I DOCUMENTACIÓ
B5: FEBRER | D5: 13 | F5: 0 | I5: 0 | L5: 0 | O5: 0 | R5: 0
D6: 14 | F6: 0 | I6: 0 | L6: 0 | O6: 0 | R6: 0
D7: 15 | F7: 0 | I7: 0 | L7: 0 | O7: 0 | R7: 0
D8: 16 | F8: 0 | I8: 0 | L8: 0 | O8: 0 | R8: 0
D9: 17 | F9: 3 | G9: Seminari 1: JavaScript | I9: 0 | L9: 0 | O9: 0 | R9: 0
D10: 18 | F10: 0 | I10: 0 | L10: 0 | O10: 0 | R10: 0
D11: 19 | F11: 0 | I11: 0 | L11: 0 | O11: 0 | R11: 0
D12: 20 | F12: 0 | I12: 0 | L12: 0 | O12: 0 | R12: 3 | S12: Seminari 2: Git
D13: 21 | F13: 0 | I13: 0 | L13: 0 | O13: 0 | R13: 0
D14: 22 | F14: 0 | I14: 0 | L14: 0 | O14: 0 | R14: 0
D15: 23 | F15: 0 | I15: 0 | L15: 0 | O15: 0 | R15: 0
D16: 24 | F16: 3 | G16: Seminari 3 y 4: TypeScript y MongoDB | I16: 0 | L16: 0 | O16: 0 | R16: 0
D17: 25 | F17: 0 | I17: 0 | L17: 0 | O17: 0 | R17: 0
D18: 26 | F18: 0 | I18: 0 | L18: 0 | O18: 0 | R18: 0
D19: 27 | F19: 0 | I19: 0 | L19: 0 | O19: 0 | R19: 1 | S19: Meetting
D20: 28 | F20: 0 | I20: 0 | L20: 0 | O20: 0 | R20: 0
B22: MARÇ | D22: 1 | F22: 0 | I22: 0 | L22: 0 | O22: 0 | R22: 0
D23: 2 | F23: 0 | I23: 0 | L23: 0 | O23: 0 | R23: 0
D24: 3 | F24: 0 | I24: 0 | L24: 0 | O24: 0 | R24: 0
D25: 4 | F25: 0 | I25: 0 | L25: 0 | O25: 0 | R25: 0
D26: 5 | F26: 0 | I26: 0 | L26: 0 | O26: 0 | R26: 0
D27: 6 | F27: 3 | G27: Seminari 5: APIRest | I27: 0 | L27: 0 | O27: 0 | R27: 1 | S27: Meetting
D28: 7 | F28: 0 | I28: 0 | L28: 0 | O28: 0 | R28: 0
D29: 8 | F29: 0 | I29: 0 | L29: 0 | O29: 0 | R29: 0
D30: 9 | F30: 0 | I30: 0 | L30: 0 | O30: 0 | R30: 0
D31: 10 | F31: 0 | I31: 3 | J31: Seminari 6: Angular | L31: 0 | O31: 0 | R31: 0
D32: 11 | F32: 0 | I32: 0 | L32: 0 | O32: 0 | R32: 0
D33: 12 | F33: 0 | I33: 0 | L33: 0 | O33: 0 | R33: 0
D34: 13 | F34: 0 | I34: 0 | L34: 0 | O34: 0 | R34: 1 | S34: Planificació SPRINT 1
D35: 14 | F35: 0 | I35: 0 | L35: 0 | O35: 0 | R35: 0
D36: 15 | F36: 0 | I36: 0 | L36: 0 | O36: 0 | R36: 0
D37: 16 | F37: 0 | I37: 0 | L37: 0 | O37: 0 | R37: 0
D38: 17 | F38: 3 | G38: Seminari 7: JWT | I38: 0 | L38: 0 | O38: 0 | R38: 0
D39: 18 | F39: 2 | G39: Desenvolupament classe Libros | I39: 0 | L39: 0 | O39: 0 | R39: 0
D40: 19 | F40: 0 | I40: 0 | L40: 0 | O40: 0 | R40: 0
D41: 20 | F41: 0 | I41: 0 | L41: 0 | O41: 0 | R41: 1 | S41: Planificació SPRINT 2
D42: 21 | F42: 0 | I42: 0 | L42: 0 | O42: 0 | R42: 0
D43: 22 | F43: 0 | I43: 0 | L43: 0 | O43: 0 | R43: 0
D44: 23 | F44: 0 | I44: 0 | L44: 0 | O44: 0 | R44: 0
...

Sheet MARC
B2: MARC | F2: BACKEND | I2: BACKOFFICE | L2: APP WEB | O2: APP MOBILE | R2: GESTIÓ I DOCUMENTACIÓ
B5: FEBRER | D5: 13 | F5: 0 | I5: 0 | L5: 0 | O5: 0 | R5: 0
D6: 14 | F6: 0 | I6: 0 | L6: 0 | O6: 0 | R6: 0
D7: 15 | F7: 0 | I7: 0 | L7: 0 | O7: 0 | R7: 0
D8: 16 | F8: 0 | I8: 0 | L8: 0 | O8: 0 | R8: 0
D9: 17 | F9: 3 | G9: Seminari 1: JavaScript | I9: 0 | L9: 0 | O9: 0 | R9: 0
D10: 18 | F10: 0 | I10: 0 | L10: 0 | O10: 0 | R10: 0
D11: 19 | F11: 0 | I11: 0 | L11: 0 | O11: 0 | R11: 0
D12: 20 | F12: 0 | I12: 0 | L12: 0 | O12: 0 | R12: 3 | S12: Seminari 2: Git
D13: 21 | F13: 0 | I13: 0 | L13: 0 | O13: 0 | R13: 0
D14: 22 | F14: 0 | I14: 0 | L14: 0 | O14: 0 | R14: 0
D15: 23 | F15: 0 | I15: 0 | L15: 0 | O15: 0 | R15: 0
D16: 24 | F16: 3 | G16: Seminari 3 y 4: TypeScript y MongoDB | I16: 0 | L16: 0 | O16: 0 | R16: 0
D17: 25 | F17: 0 | I17: 0 | L17: 0 | O17: 0 | R17: 0
D18: 26 | F18: 0 | I18: 0 | L18: 0 | O18: 0 | R18: 0
D19: 27 | F19: 0 | I19: 0 | L19: 0 | O19: 0 | R19: 1 | S19: Meetting
D20: 28 | F20: 0 | I20: 0 | L20: 0 | O20: 0 | R20: 0
B22: MARÇ | D22: 1 | F22: 0 | I22: 0 | L22: 0 | O22: 0 | R22: 0
D23: 2 | F23: 0 | I23: 0 | L23: 0 | O23: 0 | R23: 0
D24: 3 | F24: 0 | I24: 0 | L24: 0 | O24: 0 | R24: 0
D25: 4 | F25: 0 | I25: 0 | L25: 0 | O25: 0 | R25: 0
D26: 5 | F26: 0 | I26: 0 | L26: 0 | O26: 0 | R26: 0
D27: 6 | F27: 3 | G27: Seminari 5: APIRest | I27: 0 | L27: 0 | O27: 0 | R27: 1 | S27: Meetting
D28: 7 | F28: 0 | I28: 0 | L28: 0 | O28: 0 | R28: 0
D29: 8 | F29: 0 | I29: 0 | L29: 0 | O29: 0 | R29: 0
D30: 9 | F30: 0 | I30: 0 | L30: 0 | O30: 0 | R30: 0
D31: 10 | F31: 0 | I31: 3 | J31: Seminari 6: Angular | L31: 0 | O31: 0 | R31: 0
D32: 11 | F32: 0 | I32: 0 | L32: 0 | O32: 0 | R32: 0
D33: 12 | F33: 0 | I33: 0 | L33: 0 | O33: 0 | R33: 0
D34: 13 | F34: 0 | I34: 0 | L34: 0 | O34: 0 | R34: 1 | S34: Planificació SPRINT 1
D35: 14 | F35: 0 | I35: 0 | L35: 0 | O35: 0 | R35: 0
D36: 15 | F36: 0 | I36: 0 | L36: 0 | O36: 0 | R36: 0
D37: 16 | F37: 0 | I37: 0 | L37: 0 | O37: 0 | R37: 0
D38: 17 | F38: 3 | G38: Seminari 7: JWT | I38: 0 | L38: 0 | O38: 0 | R38: 0
D39: 18 | F39: 2 | G39: Desenvolupament classe Autores | I39: 0 | L39: 0 | O39: 0 | R39: 0
D40: 19 | F40: 0 | I40: 0 | L40: 0 | O40: 0 | R40: 0
D41: 20 | F41: 0 | I41: 0 | L41: 0 | O41: 0 | R41: 1 | S41: Planificació SPRINT 2
D42: 21 | F42: 0 | I42: 0 | L42: 0 | O42: 0 | R42: 0
D43: 22 | F43: 0 | I43: 0 | L43: 0 | O43: 0 | R43: 0
D44: 23 | F44: 0 | I44: 0 | L44: 0 | O44: 0 | R44: 0
...

Sheet MUYE
B2: MUYE | F2: BACKEND | I2: BACKOFFICE | L2: APP WEB | O2: APP MOBILE | R2: GESTIÓ I DOCUMENTACIÓ
B5: FEBRER | D5: 13 | F5: 0 | I5: 0 | L5: 0 | O5: 0 | R5: 0
D6: 14 | F6: 0 | I6: 0 | L6: 0 | O6: 0 | R6: 0
D7: 15 | F7: 0 | I7: 0 | L7: 0 | O7: 0 | R7: 0
D8: 16 | F8: 0 | I8: 0 | L8: 0 | O8: 0 | R8: 0
D9: 17 | F9: 3 | G9: Seminari 1: JavaScript | I9: 0 | L9: 0 | O9: 0 | R9: 0
D10: 18 | F10: 0 | I10: 0 | L10: 0 | O10: 0 | R10: 0
D11: 19 | F11: 0 | I11: 0 | L11: 0 | O11: 0 | R11: 0
D12: 20 | F12: 0 | I12: 0 | L12: 0 | O12: 0 | R12: 3 | S12: Seminari 2: Git
D13: 21 | F13: 0 | I13: 0 | L13: 0 | O13: 0 | R13: 0
D14: 22 | F14: 0 | I14: 0 | L14: 0 | O14: 0 | R14: 0
D15: 23 | F15: 0 | I15: 0 | L15: 0 | O15: 0 | R15: 0
D16: 24 | F16: 3 | G16: Seminari 3 y 4: TypeScript y MongoDB | I16: 0 | L16: 0 | O16: 0 | R16: 0
D17: 25 | F17: 0 | I17: 0 | L17: 0 | O17: 0 | R17: 0
D18: 26 | F18: 0 | I18: 0 | L18: 0 | O18: 0 | R18: 0
D19: 27 | F19: 0 | I19: 0 | L19: 0 | O19: 0 | R19: 1 | S19: Meetting
D20: 28 | F20: 0 | I20: 0 | L20: 0 | O20: 0 | R20: 0
B22: MARÇ | D22: 1 | F22: 0 | I22: 0 | L22: 0 | O22: 0 | R22: 0
D23: 2 | F23: 0 | I23: 0 | L23: 0 | O23: 0 | R23: 0
D24: 3 | F24: 0 | I24: 0 | L24: 0 | O24: 0 | R24: 0
D25: 4 | F25: 0 | I25: 0 | L25: 0 | O25: 0 | R25: 0
D26: 5 | F26: 0 | I26: 0 | L26: 0 | O26: 0 | R26: 0
D27: 6 | F27: 3 | G27: Seminari 5: APIRest | I27: 0 | L27: 0 | O27: 0 | R27: 1 | S27: Meetting
D28: 7 | F28: 0 | I28: 0 | L28: 0 | O28: 0 | R28: 0
D29: 8 | F29: 0 | I29: 0 | L29: 0 | O29: 0 | R29: 0
D30: 9 | F30: 0 | I30: 0 | L30: 0 | O30: 0 | R30: 0
D31: 10 | F31: 0 | I31: 3 | J31: Seminari 6: Angular | L31: 0 | O31: 0 | R31: 0
D32: 11 | F32: 0 | I32: 0 | L32: 0 | O32: 0 | R32: 0
D33: 12 | F33: 0 | I33: 0 | L33: 0 | O33: 0 | R33: 0
D34: 13 | F34: 0 | I34: 0 | L34: 0 | O34: 0 | R34: 1 | S34: Planificació SPRINT 1
D35: 14 | F35: 0 | I35: 0 | L35: 0 | O35: 0 | R35: 0
D36: 15 | F36: 0 | I36: 0 | L36: 0 | O36: 0 | R36: 0
D37: 16 | F37: 0 | I37: 0 | L37: 0 | O37: 0 | R37: 0
D38: 17 | F38: 4 | G38: Seminari 7: JWT + Soft Delete | I38: 2 | J38: Soft Delete | L38: 0 | O38: 0 | R38: 0
D39: 18 | F39: 0 | I39: 0 | L39: 0 | O39: 0 | R39: 0
D40: 19 | F40: 0 | I40: 0 | L40: 0 | O40: 0 | R40: 0
D41: 20 | F41: 0 | I41: 0 | L41: 0 | O41: 0 | R41: 1 | S41: Planificació SPRINT 2
D42: 21 | F42: 0 | I42: 0 | L42: 0 | O42: 0 | R42: 0
D43: 22 | F43: 0 | I43: 0 | L43: 0 | O43: 0 | R43: 0
D44: 23 | F44: 0 | I44: 0 | L44: 0 | O44: 0 | R44: 0
...

Sheet VICTOR
B2: VICTOR | F2: BACKEND | I2: BACKOFFICE | L2: APP WEB | O2: APP MOBILE | R2: GESTIÓ I DOCUMENTACIÓ
B5: FEBRER | D5: 13 | F5: 0 | I5: 0 | L5: 0 | O5: 0 | R5: 0
D6: 14 | F6: 0 | I6: 0 | L6: 0 | O6: 0 | R6: 0
D7: 15 | F7: 0 | I7: 0 | L7: 0 | O7: 0 | R7: 0
D8: 16 | F8: 0 | I8: 0 | L8: 0 | O8: 0 | R8: 0
D9: 17 | F9: 3 | G9: Seminari 1: JavaScript | I9: 0 | L9: 0 | O9: 0 | R9: 0
D10: 18 | F10: 0 | I10: 0 | L10: 0 | O10: 0 | R10: 0
D11: 19 | F11: 0 | I11: 0 | L11: 0 | O11: 0 | R11: 0
D12: 20 | F12: 0 | I12: 0 | L12: 0 | O12: 0 | R12: 3 | S12: Seminari 2: Git
D13: 21 | F13: 0 | I13: 0 | L13: 0 | O13: 0 | R13: 0
D14: 22 | F14: 0 | I14: 0 | L14: 0 | O14: 0 | R14: 0
D15: 23 | F15: 0 | I15: 0 | L15: 0 | O15: 0 | R15: 0
D16: 24 | F16: 3 | G16: Seminari 3 y 4: TypeScript y MongoDB | I16: 0 | L16: 0 | O16: 0 | R16: 0
D17: 25 | F17: 0 | I17: 0 | L17: 0 | O17: 0 | R17: 0
D18: 26 | F18: 0 | I18: 0 | L18: 0 | O18: 0 | R18: 0
D19: 27 | F19: 0 | I19: 0 | L19: 0 | O19: 0 | R19: 1 | S19: Meetting
D20: 28 | F20: 0 | I20: 0 | L20: 0 | O20: 0 | R20: 0
B22: MARÇ | D22: 1 | F22: 0 | I22: 0 | L22: 0 | O22: 0 | R22: 0
D23: 2 | F23: 0 | I23: 0 | L23: 0 | O23: 0 | R23: 0
D24: 3 | F24: 0 | I24: 0 | L24: 0 | O24: 0 | R24: 0
D25: 4 | F25: 0 | I25: 0 | L25: 0 | O25: 0 | R25: 0
D26: 5 | F26: 0 | I26: 0 | L26: 0 | O26: 0 | R26: 0
D27: 6 | F27: 3 | G27: Seminari 5: APIRest | I27: 0 | L27: 0 | O27: 0 | R27: 1 | S27: Meetting
D28: 7 | F28: 0 | I28: 0 | L28: 0 | O28: 0 | R28: 0
D29: 8 | F29: 0 | I29: 0 | L29: 0 | O29: 0 | R29: 0
D30: 9 | F30: 0 | I30: 0 | L30: 0 | O30: 0 | R30: 0
D31: 10 | F31: 0 | I31: 3 | J31: Seminari 6: Angular | L31: 0 | O31: 0 | R31: 0
D32: 11 | F32: 0 | I32: 0 | L32: 0 | O32: 0 | R32: 0
D33: 12 | F33: 0 | I33: 0 | L33: 0 | O33: 0 | R33: 0
D34: 13 | F34: 0 | I34: 0 | L34: 0 | O34: 0 | R34: 1.5 | S34: Planificació SPRINT 1
D35: 14 | F35: 0 | I35: 0 | L35: 0 | O35: 0 | R35: 0
D36: 15 | F36: 0 | I36: 0 | L36: 0 | O36: 0 | R36: 0
D37: 16 | F37: 1.5 | G37: Connexió Backoffice amb el Backend | I37: 5 | J37: Disseny i estructuració del BackOffice | L37: 0 | O37: 0 | R37: 0
D38: 17 | F38: 3 | G38: Seminari 7: JWT | I38: 0 | L38: 0 | O38: 0 | R38: 0
D39: 18 | F39: 0 | I39: 0 | L39: 0 | O39: 0 | R39: 0
D40: 19 | F40: 0 | I40: 2 | J40: Paginació al Frontend | L40: 0 | O40: 0 | R40: 0
D41: 20 | F41: 0 | I41: 0 | L41: 0 | O41: 0 | R41: 2.5 | S41: Planificació SPRINT 2 + GHERKIN
D42: 21 | F42: 0 | I42: 0 | L42: 0 | O42: 0 | R42: 0
D43: 22 | F43: 0 | I43: 0 | L43: 0 | O43: 0 | R43: 0
D44: 23 | F44: 0 | I44: 0 | L44: 0 | O44: 0 | R44: 0
...

Sheet WENJIE
B2: WENJIE | F2: BACKEND | I2: BACKOFFICE | L2: APP WEB | O2: APP MOBILE | R2: GESTIÓ I DOCUMENTACIÓ
B5: FEBRER | D5: 13 | F5: 0 | I5: 0 | L5: 0 | O5: 0 | R5: 0
D6: 14 | F6: 0 | I6: 0 | L6: 0 | O6: 0 | R6: 0
D7: 15 | F7: 0 | I7: 0 | L7: 0 | O7: 0 | R7: 0
D8: 16 | F8: 0 | I8: 0 | L8: 0 | O8: 0 | R8: 0
D9: 17 | F9: 3 | G9: Seminari 1: JavaScript | I9: 0 | L9: 0 | O9: 0 | R9: 0
D10: 18 | F10: 0 | I10: 0 | L10: 0 | O10: 0 | R10: 0
D11: 19 | F11: 0 | I11: 0 | L11: 0 | O11: 0 | R11: 0
D12: 20 | F12: 0 | I12: 0 | L12: 0 | O12: 0 | R12: 3 | S12: Seminari 2: Git
D13: 21 | F13: 0 | I13: 0 | L13: 0 | O13: 0 | R13: 0
D14: 22 | F14: 0 | I14: 0 | L14: 0 | O14: 0 | R14: 0
D15: 23 | F15: 0 | I15: 0 | L15: 0 | O15: 0 | R15: 0
D16: 24 | F16: 3 | G16: Seminari 3 y 4: TypeScript y MongoDB | I16: 0 | L16: 0 | O16: 0 | R16: 0
D17: 25 | F17: 0 | I17: 0 | L17: 0 | O17: 0 | R17: 0
D18: 26 | F18: 0 | I18: 0 | L18: 0 | O18: 0 | R18: 0
D19: 27 | F19: 0 | I19: 0 | L19: 0 | O19: 0 | R19: 1 | S19: Meetting
D20: 28 | F20: 0 | I20: 0 | L20: 0 | O20: 0 | R20: 0
B22: MARÇ | D22: 1 | F22: 0 | I22: 0 | L22: 0 | O22: 0 | R22: 0
D23: 2 | F23: 0 | I23: 0 | L23: 0 | O23: 0 | R23: 0
D24: 3 | F24: 0 | I24: 0 | L24: 0 | O24: 0 | R24: 0
D25: 4 | F25: 0 | I25: 0 | L25: 0 | O25: 0 | R25: 0
D26: 5 | F26: 0 | I26: 0 | L26: 0 | O26: 0 | R26: 0
D27: 6 | F27: 3 | G27: Seminari 5: APIRest | I27: 0 | L27: 0 | O27: 0 | R27: 1 | S27: Meetting
D28: 7 | F28: 0 | I28: 0 | L28: 0 | O28: 0 | R28: 0
D29: 8 | F29: 0 | I29: 0 | L29: 0 | O29: 0 | R29: 0
D30: 9 | F30: 0 | I30: 0 | L30: 0 | O30: 0 | R30: 0
D31: 10 | F31: 0 | I31: 3 | J31: Seminari 6: Angular | L31: 0 | O31: 0 | R31: 0
D32: 11 | F32: 0 | I32: 0 | L32: 0 | O32: 0 | R32: 0
D33: 12 | F33: 0 | I33: 0 | L33: 0 | O33: 0 | R33: 0
D34: 13 | F34: 0 | I34: 0 | L34: 0 | O34: 0 | R34: 1 | S34: Planificació SPRINT 1
D35: 14 | F35: 0 | I35: 0 | L35: 0 | O35: 0 | R35: 0
D36: 15 | F36: 0 | I36: 0 | L36: 0 | O36: 0 | R36: 0
D37: 16 | F37: 0 | I37: 0 | L37: 0 | O37: 0 | R37: 0
D38: 17 | F38: 3 | G38: Seminari 7: JWT | I38: 0 | L38: 0 | O38: 0 | R38: 0
D39: 18 | F39: 2 | G39: Desenvolupament classe Usuari | I39: 0 | L39: 0 | O39: 0 | R39: 0
D40: 19 | F40: 1.5 | G40: Busqueda de libro por ISBN | I40: 1.5 | J40: Busqueda de libro por ISBN | L40: 0 | O40: 0 | R40: 0
D41: 20 | F41: 0 | I41: 0 | L41: 0 | O41: 0 | R41: 1 | S41: Planificació SPRINT 2
D42: 21 | F42: 0 | I42: 0 | L42: 0 | O42: 0 | R42: 0
D43: 22 | F43: 0 | I43: 0 | L43: 0 | O43: 0 | R43: 0
D44: 23 | F44: 0 | I44: 0 | L44: 0 | O44: 0 | R44: 0
...

Sheet SCRUM
B2: SPRINT | C2: PUNTS | D2: REF. | E2: DESCRIPCIÓ
B4: 1 | D4: S1.1 | E4: Yo, como usuario del BackOffice, debería poder deshabilitar a un usuario. | G4: Scrum Master | H4: Victor
D5: S1.2 | E5: Yo, como administrador de ViveBook, deberia poder gestionar la base de datos sin necesidad de tener conocimientos técnicos. | G5: Product Owner | H5: Alba i Marc
D6: S1.3 | E6: Yo, como usuario admin, prefiero ver la información de forma paginada y organizada. | G6: Desenvolupament | H6: Wenjie i Muye
D7: S1.4 | E7: Yo, como colaborador de este proyecto, debería ser capaz de organizar mis versiones de forma clara y práctica.
D8: S1.5 | E8: Yo, como consumidor de la RestAPI, debería ser capaz de hacer cualquier consulta sobre Libros.
D9: S1.6 | E9: Yo, como consumidor de la RestAPI, debería ser capaz de hacer cualquier consulta sobre Autores.
D10: S1.7 | E10: Yo, como consumidor de la RestAPI, debería ser capaz de hacer cualquier consulta sobre Usuarios.
D11: S1.8 | E11: Yo, como usuario, sea capaz de hacer un post a partir de un isbn y que se rellene los datos del libro automaticamente.
B12: 2 | C12: 8 | D12: S2.1 | E12: Como usuario registrado, quiero autenticarme mediante JWT para acceder de forma segura a las funcionalidades privadas de la WebApp. | G12: Scrum Master | H12: Victor
C13: 3 | D13: S2.2 | E13: Como usuario registrado, quiero iniciar sesión en la WebApp para acceder a mi cuenta y a las funcionalidades privadas. | G13: Product Owner | H13: Wenjie i Muye
C14: 3 | D14: S2.3 | E14: Como visitante, quiero crear una cuenta en la WebApp para poder acceder a las funcionalidades privadas como usuario registrado. | G14: Desenvolupament | H14: Alba i Marc
C15: 5 | D15: S2.4 | E15: Como usuario, quiero una interfaz clara y usable para navegar y utilizar la aplicación de forma sencilla.
